Workbook

Sheet Dataset
A1: BU | B1: DISTRIBUTION_CHANNEL | C1: PERIOD | D1: ACCOUNT_ID | E1: ACCOUNT | F1: CY(Override) | G1: CY(Existing) | H1: Granularity | I1: Status | J1: Jira | K1: Comments
A2: Hong Kong | B2: Agency | C2: 46173 | D2: AG0002 | E2: Submitted APE | F2: 91269333 | H2: Monthly | I2: Completed
A3: Hong Kong | B3: Agency | C3: 46173 | D3: AG0016 | E3: # of 1-Month Active Agents | F3: 4376 | H3: Monthly | I3: Completed
A4: Hong Kong | B4: Agency | C4: 46173 | D4: AG0016_1 | E4: # of 1-Month Active Agents in 0-1M | F4: 45 | H4: Monthly | I4: Completed
A5: Hong Kong | B5: Agency | C5: 46173 | D5: AG0016_10 | E5: # of 1-Month Active Agents in UM | F5: 634 | H5: Monthly | I5: Completed
A6: Hong Kong | B6: Agency | C6: 46173 | D6: AG0016_11 | E6: # of 1-Month Active Agents in Leaders above UM | F6: 696 | H6: Monthly | I6: Completed
A7: Hong Kong | B7: Agency | C7: 46173 | D7: AG0016_12 | E7: # of 1-Month Active Top-tier Agents | F7: 2846 | H7: Monthly | I7: Completed
A8: Hong Kong | B8: Agency | C8: 46173 | D8: AG0016_12_1 | E8: # of 1-Month Active Agents in pro-rated MDRT agents (>100% of pro-rated achievement) | F8: 1806 | H8: Monthly | I8: Completed
A9: Hong Kong | B9: Agency | C9: 46173 | D9: AG0016_12_2 | E9: # of 1-Month Active Agents in pro-rated MDRT agents (70-99% of pro-rated achievement) | F9: 552 | H9: Monthly | I9: Completed
A10: Hong Kong | B10: Agency | C10: 46173 | D10: AG0016_12_3 | E10: # of 1-Month Active Agents in pro-rated MDRT agents (50-69% of pro-rated achievement) | F10: 488 | H10: Monthly | I10: Completed
A11: Hong Kong | B11: Agency | C11: 46173 | D11: AG0016_2 | E11: # of 1-Month Active Agents in 2-3M | F11: 156 | H11: Monthly | I11: Completed
A12: Hong Kong | B12: Agency | C12: 46173 | D12: AG0016_3 | E12: # of 1-Month Active Agents in 4-12M | F12: 589 | H12: Monthly | I12: Completed
A13: Hong Kong | B13: Agency | C13: 46173 | D13: AG0016_4 | E13: # of 1-Month Active Agents 13+M | F13: 3586 | H13: Monthly | I13: Completed
... A142: Vietnam | B142: Agency | C142: 46173 | D142: AG0062_6 | E142: # of pro-rated MDRT agents (70-99%) | F142: 179 | H142: Monthly | I142: Completed
A143: Philippines | B143: Agency | C143: 2026-06-30 | D143: =VLOOKUP(E143,KPI_Mapping!B:G,6,FALSE) -> AG0029 | E143: Total agent headcount (end of period) | F143: 6237 | H143: monthly | I143: Completed
A144: Philippines | B144: Agency | C144: 2026-06-30 | D144: =VLOOKUP(E144,KPI_Mapping!B:G,6,FALSE) -> AG0016 | E144: # of 1-Month Active Agents | F144: 1438 | H144: monthly | I144: Completed
A145: Philippines | B145: Agency | C145: 2026-06-30 | D145: =VLOOKUP(E145,KPI_Mapping!B:G,6,FALSE) -> AG0020 | E145: Net Case Count - Agency | F145: 2025 | H145: monthly | I145: Completed
A146: Philippines | B146: Agency | C146: 2026-06-30 | D146: =VLOOKUP(E146,KPI_Mapping!B:G,6,FALSE) -> AG0061 | E146: New Leaders 3M Activation Rate (by cohort) | F146: 1 | H146: monthly | I146: Completed
A147: Philippines | B147: Agency | C147: 2026-06-30 | D147: =VLOOKUP(E147,KPI_Mapping!B:G,6,FALSE) -> AG0061_1 | E147: New Leaders 3M Activation Rate (by cohort) (numerator) | F147: 2 | H147: monthly | I147: Completed
A148: Philippines | B148: Agency | C148: 2026-06-30 | D148: =VLOOKUP(E148,KPI_Mapping!B:G,6,FALSE) -> AG0061_2 | E148: New Leaders 3M Activation Rate (by cohort) (denominator) | F148: 2 | H148: monthly | I148: Completed
A149: Philippines | B149: Agency | C149: 2026-06-30 | D149: =VLOOKUP(E149,KPI_Mapping!B:G,6,FALSE) -> AG0072_1 | E149: # of Newly Demoted UM | F149: 8 | H149: monthly | I149: Completed
A150: Philippines | B150: Agency | C150: 2026-06-30 | D150: =VLOOKUP(E150,KPI_Mapping!B:G,6,FALSE) -> AG0072_2 | E150: # of Newly Demoted Leaders above UM | F150: 2 | H150: monthly | I150: Completed
A151: Philippines | B151: Agency | C151: 2026-06-30 | D151: =VLOOKUP(E151,KPI_Mapping!B:G,6,FALSE) -> AG0046 | E151: No of Terminations | F151: 1461 | H151: monthly | I151: Completed
A152: Philippines | B152: Agency | C152: 2026-06-30 | D152: =VLOOKUP(E152,KPI_Mapping!B:G,6,FALSE) -> AG0055 | E152: # of Active Recruiting Leaders | F152: 99 | H152: monthly | I152: Completed
A153: Philippines | B153: Agency | C153: 2026-06-30 | D153: =VLOOKUP(E153,KPI_Mapping!B:G,6,FALSE) -> AG0055_1 | E153: # of leaders with >1 YTD recruit | F153: 396 | H153: monthly | I153: Completed
A154: Philippines | B154: Agency | C154: 2026-06-30 | D154: =VLOOKUP(E154,KPI_Mapping!B:G,6,FALSE) -> AG0060 | E154: # of Newly Promoted UM | F154: 1 | H154: monthly | I154: Completed
... A177: Hong Kong | B177: Agency | C177: 2026-07-02 | D177: =VLOOKUP(E177,KPI_Mapping!B:G,6,FALSE) -> AG0055 | E177: # of Active Recruiting Leaders | F177: 69 | H177: daily | I177: Completed
A178: China | B178: Agency | C178: 46142 | D178: =VLOOKUP(E178,KPI_Mapping!B:G,6,FALSE) -> AG0043 | E178: New Recruits 3M Activation # | F178: 124 | H178: monthly | I178: Completed | J178: DK-1680
A179: China | B179: Agency | C179: 46173 | D179: =VLOOKUP(E179,KPI_Mapping!B:G,6,FALSE) -> AG0043 | E179: New Recruits 3M Activation # | F179: 101 | H179: monthly | I179: Completed | J179: DK-1680
A180: Cambodia | B180: Agency | C180: 46053 | D180: =VLOOKUP(E180,KPI_Mapping!D:G,4,FALSE) -> AG0051 | E180: Total # of Leaders (end of period) | F180: 124 | H180: monthly | I180: Completed | J180: DK-1636
A181: Cambodia | B181: Agency | C181: 46081 | D181: =VLOOKUP(E181,KPI_Mapping!D:G,4,FALSE) -> AG0051 | E181: Total # of Leaders (end of period) | F181: 126 | H181: monthly | I181: Completed | J181: DK-1636
A182: Cambodia | B182: Agency | C182: 46173 | D182: AG0016 | E182: # of 1-Month Active Agents | F182: 52 | H182: Monthly | I182: Completed | J182: DK-1516
A183: Cambodia | B183: Agency | C183: 46142 | D183: AG0016 | E183: # of 1-Month Active Agents | F183: 50 | H183: Monthly | I183: Completed | J183: DK-1516
A184: Cambodia | B184: Agency | C184: 46112 | D184: AG0016 | E184: # of 1-Month Active Agents | F184: 102 | H184: Monthly | I184: Completed | J184: DK-1516
A185: Cambodia | B185: Agency | C185: 46081 | D185: AG0016 | E185: # of 1-Month Active Agents | F185: 67 | H185: Monthly | I185: Completed | J185: DK-1516
A186: Cambodia | B186: Agency | C186: 46053 | D186: AG0016 | E186: # of 1-Month Active Agents | F186: 55 | H186: Monthly | I186: Completed | J186: DK-1516
A187: China | B187: Agency | C187: 46053 | D187: AG0060 | E187: # of Newly Promoted UM | F187: 19 | H187: Monthly | J187: DK-1714
A188: China | B188: Agency | C188: 46081 | D188: AG0060 | E188: # of Newly Promoted UM | F188: 18 | H188: Monthly | J188: DK-1714
A189: China | B189: Agency | C189: 46112 | D189: AG0060 | E189: # of Newly Promoted UM | F189: 13 | H189: Monthly | J189: DK-1714
A190: China | B190: Agency | C190: 46142 | D190: AG0060 | E190: # of Newly Promoted UM | F190: 37 | H190: Monthly | J190: DK-1714
...

Sheet Sheet2
L18: Jan | M18: Feb | N18: Mar | O18: Apr | P18: May | Q18: Jun
L19: Actuals | M19: Actuals | N19: Actuals | O19: Actuals | P19: Actuals | Q19: Actuals | V19: Jan | W19: Feb | X19: Mar | Y19: Apr | Z19: May | AA19: Jun
I20: HK | J20: Promoted UM | K20: Cheatsheet | L20: 33 | M20: 22 | N20: 10 | O20: 27 | P20: 17 | Q20: 26 | U20: Denominator | V20: 187 | W20: 239 | X20: 251 | Y20: 233 | Z20: 146 | AA20: 302
K21: PBI | L21: 33 | M21: 23 | N21: 10 | O21: 27 | P21: 17 | Q21: 17 | U21: Ratio | V21: 0.58 | W21: 0.57670127 | X21: 0.54 | Y21: 0.53 | Z21: 0.69 | AA21: 0.72
V22: =V20*V21 -> 108.46 | W22: =W20*W21 -> 137.8316 | X22: =X20*X21 -> 135.54 | Y22: =Y20*Y21 -> 123.49 | Z22: =Z20*Z21 -> 100.74 | AA22: =AA20*AA21 -> 217.44
J23: Promoted above UM | K23: Cheatsheet | L23: 30 | M23: 25 | N23: 55 | O23: 30 | P23: 25 | Q23: 30
K24: PBI | L24: 29 | M24: 0 | N24: 3 | O24: 17 | P24: 6 | Q24: 9
I26: VN | J26: Promoted UM | K26: Cheatsheet | L26: 44 | M26: 67 | N26: 84 | O26: 121 | P26: 157 | Q26: 205
K27: PBI | L27: 43 | M27: 22 | N27: 9 | O27: 34 | P27: 33 | Q27: 41
J29: Promoted above UM | K29: Cheatsheet | L29: 1 | M29: 2 | N29: 4 | O29: 6 | P29: 8 | Q29: 10
K30: PBI | L30: 7 | M30: 4 | N30: 4 | O30: 13 | P30: 10 | Q30: 8
I34: MY | J34: Promoted UM | K34: Cheatsheet | L34: 6 | M34: 6 | N34: 9 | O34: 9 | P34: 10 | Q34: 11
K35: PBI | L35: 6 | M35: 0 | N35: 3 | O35: 2 | P35: 2 | Q35: 1
J37: Promoted above UM | K37: Cheatsheet | L37: 0 | M37: 0 | N37: 0 | O37: 0 | P37: 1 | Q37: 1
K38: PBI | L38: Hourglass | M38: Hourglass | N38: 0 | O38: 0 | P38: 1 | Q38: 0
W40: Jan | X40: Feb | Y40: Mar | Z40: Apr | AA40: May | AB40: Jun
I41: ID | J41: Promoted UM | K41: Local POC | L41: 53 | M41: 12 | N41: 9 | O41: 11 | P41: 13 | Q41: 25 | U41: Promoted UM | V41: Branch | W41: 19 | X41: 2 | Y41: 2 | Z41: 4 | AA41: 3 | AB41: 8
K42: PBI | L42: 53 | M42: 12 | N42: 9 | O42: 12 | P42: 14 | Q42: 25 | V42: GA | W42: 34 | X42: 10 | Y42: 7 | Z42: 7 | AA42: 10 | AB42: 17
V43: Sum | W43: =SUM(W41:W42) -> 53 | X43: =SUM(X41:X42) -> 12 | Y43: =SUM(Y41:Y42) -> 9 | Z43: =SUM(Z41:Z42) -> 11 | AA43: =SUM(AA41:AA42) -> 13 | AB43: =SUM(AB41:AB42) -> 25
J44: Promoted above UM | K44: Local POC | L44: 15 | M44: 3 | N44: 5 | O44: 1 | P44: 4 | Q44: 6
K45: PBI | L45: 16 | M45: 3 | N45: 5 | O45: 1 | P45: 4 | Q45: 7 | U45: Promoted above UM | V45: Branch | W45: 7 | X45: 0 | Y45: 0 | Z45: 0 | AA45: 3 | AB45: 2
V46: GA | W46: 8 | X46: 3 | Y46: 5 | Z46: 1 | AA46: 1 | AB46: 4
J47: Leader Promotions | K47: Local POC | L47: =L41+L44 -> 68 | M47: =M41+M44 -> 15 | N47: =N41+N44 -> 14 | O47: =O41+O44 -> 12 | P47: =P41+P44 -> 17 | Q47: =Q41+Q44 -> 31 | V47: sum | W47: =SUM(W45:W46) -> 15 | X47: =SUM(X45:X46) -> 3 | Y47: =SUM(Y45:Y46) -> 5 | Z47: =SUM(Z45:Z46) -> 1 | AA47: =SUM(AA45:AA46) -> 4 | AB47: =SUM(AB45:AB46) -> 6
K48: PBI | L48: =L42+L45 -> 69 | M48: =M42+M45 -> 15 | N48: =N42+N45 -> 14 | O48: =O42+O45 -> 13 | P48: =P42+P45 -> 18 | Q48: =Q42+Q45 -> 32
H50: SG: EDL
K51: 46048 | L51: 46079 | M51: 46107 | N51: 46138 | O51: 46168 | P51: 46199 | Q51: 46229
I52: MAG | J52: No. of Newly Promoted Unit Manager | K52: 2 | L52: 1 | M52: 0 | N52: 1 | O52: 0 | P52: 2 | Q52: 0
I53: MFA | J53: No. of Newly Promoted Unit Manager | K53: 7 | L53: 1 | M53: 0 | N53: 0 | O53: 2 | P53: 1 | Q53: 3
I55: MAG | J55: Promoted above UM | K55: 1 | L55: 0 | M55: 0 | N55: 0 | O55: 0 | P55: 0 | Q55: 0 | U55: Branch | V55: 46048 | W55: 46079 | X55: 46107 | Y55: 46138 | Z55: 46168 | AA55: 46199
I56: MFA | J56: Promoted above UM | K56: 1 | L56: 0 | M56: 0 | N56: 0 | O56: 0 | P56: 1 | Q56: 0 | U56: # of Newly Promoted UM | V56: 19 | W56: 2 | X56: 2 | Y56: 4 | Z56: 3 | AA56: 8
K57: =SUM(K52:K56) -> 11 | L57: =SUM(L52:L56) -> 2 | M57: =SUM(M52:M56) -> 0 | N57: =SUM(N52:N56) -> 1 | O57: =SUM(O52:O56) -> 2 | P57: =SUM(P52:P56) -> 4 | Q57: =SUM(Q52:Q56) -> 3 | U57: # of Newly Promoted Leaders above UM | V57: 7 | W57: 0 | X57: 0 | Y57: 0 | Z57: 3 | AA57: 2
U59: GA | V59: 46048 | W59: 46079 | X59: 46107 | Y59: 46138 | Z59: 46168 | AA59: 46199
U60: # of Newly Promoted UM | V60: 34 | W60: 10 | X60: 7 | Y60: 7 | Z60: 10 | AA60: 17
U61: # of Newly Promoted Leaders above UM | V61: 8 | W61: 3 | X61: 5 | Y61: 1 | Z61: 1 | AA61: 4
U63: # of Newly Promoted UM | V63: =V56+V60 -> 53 | W63: =W56+W60 -> 12 | X63: =X56+X60 -> 9 | Y63: =Y56+Y60 -> 11 | Z63: =Z56+Z60 -> 13 | AA63: =AA56+AA60 -> 25
H64: SG: From Local POC | U64: # of Newly Promoted Leaders above UM | V64: =V57+V61 -> 15 | W64: =W57+W61 -> 3 | X64: =X57+X61 -> 5 | Y64: =Y57+Y61 -> 1 | Z64: =Z57+Z61 -> 4 | AA64: =AA57+AA61 -> 6
K65: 46048 | L65: 46079 | M65: 46107 | N65: 46138 | O65: 46168 | P65: 46199 | U65: Promoted leader: | V65: =V63+V64 -> 68 | W65: =W63+W64 -> 15 | X65: =X63+X64 -> 14 | Y65: =Y63+Y64 -> 12 | Z65: =Z63+Z64 -> 17 | AA65: =AA63+AA64 -> 31
I66: MAG | J66: No. of Newly Promoted Unit Manager | K66: 2 | L66: 1 | M66: 0 | N66: 1 | O66: 0 | P66: 2
I67: MFA | J67: No. of Newly Promoted Unit Manager | K67: 7 | L67: 1 | M67: 0 | N67: 0 | O67: 2 | P67: 1
I69: MAG | J69: Promoted above UM | K69: 1
...

Sheet Sheet1
A2: Key | B2: BU | C2: ACCOUNT_ID | D2: ACCOUNT | E2: Source | G2: Key | H2: BU | I2: KPI_ID | J2: KPI_Name | K2: Source | P2: KPI_Name | Q2: KPI_ID
A3: =B3&C3 -> Hong KongAG0002 | B3: Hong Kong | C3: AG0002 | D3: Submitted APE | E3: =VLOOKUP(A3,G:K,5,FALSE) -> #N/A | G3: =H3&I3 -> Hong KongAG0016 | H3: Hong Kong | I3: AG0016 | J3: # of 1-Month Active Agents | K3: EDL | P3: # of 1-Month Active Agents | Q3: =VLOOKUP(P3,KPI_Mapping!B:G,6,FALSE) -> AG0016
A4: =B4&C4 -> Hong KongAG0016 | B4: Hong Kong | C4: AG0016 | D4: # of 1-Month Active Agents | E4: =VLOOKUP(A4,G:K,5,FALSE) -> EDL | G4: =H4&I4 -> Hong KongAG0020 | H4: Hong Kong | I4: AG0020 | J4: Net Case Count - Agency | K4: EDL | P4: Net Case Count - Agency | Q4: =VLOOKUP(P4,KPI_Mapping!B:G,6,FALSE) -> AG0020
A5: =B5&C5 -> Hong KongAG0016_1 | B5: Hong Kong | C5: AG0016_1 | D5: # of 1-Month Active Agents in 0-1M | E5: =VLOOKUP(A5,G:K,5,FALSE) -> #N/A | G5: =H5&I5 -> Hong KongAG0029 | H5: Hong Kong | I5: AG0029 | J5: Total agent headcount (end of period) | K5: EDL | P5: Total agent headcount (end of period) | Q5: =VLOOKUP(P5,KPI_Mapping!B:G,6,FALSE) -> AG0029
A6: =B6&C6 -> Hong KongAG0016_10 | B6: Hong Kong | C6: AG0016_10 | D6: # of 1-Month Active Agents in UM | E6: =VLOOKUP(A6,G:K,5,FALSE) -> #N/A | G6: =H6&I6 -> Hong KongAG0038 | H6: Hong Kong | I6: AG0038 | J6: New recruits | K6: EDL | P6: New recruits | Q6: =VLOOKUP(P6,KPI_Mapping!B:G,6,FALSE) -> AG0038
A7: =B7&C7 -> Hong KongAG0016_11 | B7: Hong Kong | C7: AG0016_11 | D7: # of 1-Month Active Agents in Leaders above UM | E7: =VLOOKUP(A7,G:K,5,FALSE) -> #N/A | G7: =H7&I7 -> Hong KongAG0041 | H7: Hong Kong | I7: AG0041 | J7: # of 6-90 agents | K7: EDL | P7: # of 6-90 agents | Q7: =VLOOKUP(P7,KPI_Mapping!B:G,6,FALSE) -> AG0041
A8: =B8&C8 -> Hong KongAG0016_12 | B8: Hong Kong | C8: AG0016_12 | D8: # of 1-Month Active Top-tier Agents | E8: =VLOOKUP(A8,G:K,5,FALSE) -> #N/A | G8: =H8&I8 -> Hong KongAG0043 | H8: Hong Kong | I8: AG0043 | J8: New Recruits 3M Activation # | K8: EDL | P8: New Recruits 3M Activation # | Q8: =VLOOKUP(P8,KPI_Mapping!B:G,6,FALSE) -> AG0043
A9: =B9&C9 -> Hong KongAG0016_12_1 | B9: Hong Kong | C9: AG0016_12_1 | D9: # of 1-Month Active Agents in pro-rated MDRT agents (>100% of pro-rated achievement) | E9: =VLOOKUP(A9,G:K,5,FALSE) -> #N/A | G9: =H9&I9 -> Hong KongAG0046 | H9: Hong Kong | I9: AG0046 | J9: No of Terminations | K9: EDL | P9: No of Terminations | Q9: =VLOOKUP(P9,KPI_Mapping!B:G,6,FALSE) -> AG0046
A10: =B10&C10 -> Hong KongAG0016_12_2 | B10: Hong Kong | C10: AG0016_12_2 | D10: # of 1-Month Active Agents in pro-rated MDRT agents (70-99% of pro-rated achievement) | E10: =VLOOKUP(A10,G:K,5,FALSE) -> #N/A | G10: =H10&I10 -> Hong KongAG0051 | H10: Hong Kong | I10: AG0051 | J10: Total # of Leaders (end of period) | K10: EDL | P10: Total # of Leaders (end of period) | Q10: =VLOOKUP(P10,KPI_Mapping!B:G,6,FALSE) -> AG0051
A11: =B11&C11 -> Hong KongAG0016_12_3 | B11: Hong Kong | C11: AG0016_12_3 | D11: # of 1-Month Active Agents in pro-rated MDRT agents (50-69% of pro-rated achievement) | E11: =VLOOKUP(A11,G:K,5,FALSE) -> #N/A | G11: =H11&I11 -> Hong KongAG0051_1 | H11: Hong Kong | I11: AG0051_1 | J11: Total # of Unit Managers | K11: EDL | P11: Total # of Unit Managers | Q11: =VLOOKUP(P11,KPI_Mapping!B:G,6,FALSE) -> AG0051_1
A12: =B12&C12 -> Hong KongAG0016_2 | B12: Hong Kong | C12: AG0016_2 | D12: # of 1-Month Active Agents in 2-3M | E12: =VLOOKUP(A12,G:K,5,FALSE) -> #N/A | G12: =H12&I12 -> Hong KongAG0051_2 | H12: Hong Kong | I12: AG0051_2 | J12: Total # of Leaders above Unit Manager level | K12: EDL | P12: Total # of Leaders above Unit Manager level | Q12: =VLOOKUP(P12,KPI_Mapping!B:G,6,FALSE) -> AG0051_2
A13: =B13&C13 -> Hong KongAG0016_3 | B13: Hong Kong | C13: AG0016_3 | D13: # of 1-Month Active Agents in 4-12M | E13: =VLOOKUP(A13,G:K,5,FALSE) -> #N/A | G13: =H13&I13 -> Hong KongAG0054 | H13: Hong Kong | I13: AG0054 | J13: Total # of Agents below Unit Manager level (end of period) | K13: Not Applicable | P13: Total # of Agents below Unit Manager level (end of period) | Q13: =VLOOKUP(P13,KPI_Mapping!B:G,6,FALSE) -> AG0054
A14: =B14&C14 -> Hong KongAG0016_4 | B14: Hong Kong | C14: AG0016_4 | D14: # of 1-Month Active Agents 13+M | E14: =VLOOKUP(A14,G:K,5,FALSE) -> #N/A | G14: =H14&I14 -> Hong KongAG0055 | H14: Hong Kong | I14: AG0055 | J14: # of Active Recruiting Leaders | K14: EDL | P14: # of Active Recruiting Leaders | Q14: =VLOOKUP(P14,KPI_Mapping!B:G,6,FALSE) -> AG0055
... A17: =B17&C17 -> Hong KongAG0018_1 | B17: Hong Kong | C17: AG0018_1 | D17: # of 3-Month Active Agents in 0-1M | E17: =VLOOKUP(A17,G:K,5,FALSE) -> #N/A | G17: =H17&I17 -> Hong KongAG0060_1 | H17: Hong Kong | I17: AG0060_1 | J17: # of Newly Promoted Leaders above UM | K17: EDL | P17: # of Newly Promoted Leaders above UM | Q17: =VLOOKUP(P17,KPI_Mapping!B:G,6,FALSE) -> AG0060_1
A18: =B18&C18 -> Hong KongAG0018_2 | B18: Hong Kong | C18: AG0018_2 | D18: # of 3-Month Active Agents in 2-3M | E18: =VLOOKUP(A18,G:K,5,FALSE) -> #N/A | G18: =H18&I18 -> #N/A | H18: Hong Kong | I18: #N/A | J18: # of Total Leader Promotions | K18: Anaplan Calculated | P18: # of Total Leader Promotions | Q18: =VLOOKUP(P18,KPI_Mapping!B:G,6,FALSE) -> #N/A
A19: =B19&C19 -> Hong KongAG0018_3 | B19: Hong Kong | C19: AG0018_3 | D19: # of 3-Month Active Agents in 4-12M | E19: =VLOOKUP(A19,G:K,5,FALSE) -> #N/A | G19: =H19&I19 -> Hong KongAG0072_1 | H19: Hong Kong | I19: AG0072_1 | J19: # of Newly Demoted UM | K19: EDL | P19: # of Newly Demoted UM | Q19: =VLOOKUP(P19,KPI_Mapping!B:G,6,FALSE) -> AG0072_1
A20: =B20&C20 -> Hong KongAG0018_4 | B20: Hong Kong | C20: AG0018_4 | D20: # of 3-Month Active Agents 13+M | E20: =VLOOKUP(A20,G:K,5,FALSE) -> #N/A | G20: =H20&I20 -> Hong KongAG0072_2 | H20: Hong Kong | I20: AG0072_2 | J20: # of Newly Demoted Leaders above UM | K20: EDL | P20: # of Newly Demoted Leaders above UM | Q20: =VLOOKUP(P20,KPI_Mapping!B:G,6,FALSE) -> AG0072_2
A21: =B21&C21 -> Hong KongAG0020 | B21: Hong Kong | C21: AG0020 | D21: Net Case Count - Agency | E21: =VLOOKUP(A21,G:K,5,FALSE) -> EDL | G21: =H21&I21 -> Hong KongAG0061 | H21: Hong Kong | I21: AG0061 | J21: New Leaders 3M Activation Rate (by cohort) | K21: EDL | P21: New Leaders 3M Activation Rate (by cohort) | Q21: =VLOOKUP(P21,KPI_Mapping!B:G,6,FALSE) -> AG0061
A22: =B22&C22 -> Hong KongAG0020_1 | B22: Hong Kong | C22: AG0020_1 | D22: Net Case Count - Agency in 0-1M | E22: =VLOOKUP(A22,G:K,5,FALSE) -> #N/A | G22: =H22&I22 -> Hong KongAG0061_1 | H22: Hong Kong | I22: AG0061_1 | J22: New Leaders 3M Activation Rate (by cohort) (numerator) | K22: EDL | P22: New Leaders 3M Activation Rate (by cohort) (numerator) | Q22: =VLOOKUP(P22,KPI_Mapping!B:G,6,FALSE) -> AG0061_1
A23: =B23&C23 -> Hong KongAG0020_10 | B23: Hong Kong | C23: AG0020_10 | D23: Net Case Count - Agency in UM | E23: =VLOOKUP(A23,G:K,5,FALSE) -> #N/A | G23: =H23&I23 -> Hong KongAG0061_2 | H23: Hong Kong | I23: AG0061_2 | J23: New Leaders 3M Activation Rate (by cohort) (denominator) | K23: EDL | P23: New Leaders 3M Activation Rate (by cohort) (denominator) | Q23: =VLOOKUP(P23,KPI_Mapping!B:G,6,FALSE) -> AG0061_2
A24: =B24&C24 -> Hong KongAG0020_11 | B24: Hong Kong | C24: AG0020_11 | D24: Net Case Count - Agency in Leaders above UM | E24: =VLOOKUP(A24,G:K,5,FALSE) -> #N/A | G24: =H24&I24 -> Hong KongAG0062 | H24: Hong Kong | I24: AG0062 | J24: # of pro-rated MDRT agents (100%) | K24: EDL | P24: # of pro-rated MDRT agents (100%) | Q24: =VLOOKUP(P24,KPI_Mapping!B:G,6,FALSE) -> AG0062
A25: =B25&C25 -> Hong KongAG0020_12 | B25: Hong Kong | C25: AG0020_12 | D25: Net Case Count - Agency in Top-tier Agents | E25: =VLOOKUP(A25,G:K,5,FALSE) -> #N/A | G25: =H25&I25 -> Hong KongAG0062_6 | H25: Hong Kong | I25: AG0062_6 | J25: # of pro-rated MDRT agents (70-99%) | K25: EDL | P25: # of pro-rated MDRT agents (70-99%) | Q25: =VLOOKUP(P25,KPI_Mapping!B:G,6,FALSE) -> AG0062_6
A26: =B26&C26 -> Hong KongAG0020_12_1 | B26: Hong Kong | C26: AG0020_12_1 | D26: Net Case Count - Agency in pro-rated MDRT agents (>100% of pro-rated achievement) | E26: =VLOOKUP(A26,G:K,5,FALSE) -> #N/A | G26: =H26&I26 -> Hong KongAG0062_7 | H26: Hong Kong | I26: AG0062_7 | J26: # of pro-rated MDRT agents (50-69%) | K26: EDL | P26: # of pro-rated MDRT agents (50-69%) | Q26: =VLOOKUP(P26,KPI_Mapping!B:G,6,FALSE) -> AG0062_7
A27: =B27&C27 -> Hong KongAG0020_12_2 | B27: Hong Kong | C27: AG0020_12_2 | D27: Net Case Count - Agency in pro-rated MDRT agents (70-99% of pro-rated achievement) | E27: =VLOOKUP(A27,G:K,5,FALSE) -> #N/A | G27: =H27&I27 -> Hong KongAG0062_8 | H27: Hong Kong | I27: AG0062_8 | J27: # of Top-tier agents | K27: EDL | P27: # of Top-tier agents | Q27: =VLOOKUP(P27,KPI_Mapping!B:G,6,FALSE) -> AG0062_8
A28: =B28&C28 -> Hong KongAG0020_12_3 | B28: Hong Kong | C28: AG0020_12_3 | D28: Net Case Count - Agency in pro-rated MDRT agents (50-69% of pro-rated achievement) | E28: =VLOOKUP(A28,G:K,5,FALSE) -> #N/A | G28: =H28&I28 -> Hong KongAG0073 | H28: Hong Kong | I28: AG0073 | J28: Manulife Pro Qualifiers - Total | K28: Manual Anaplan Input | P28: Manulife Pro Qualifiers - Total | Q28: =VLOOKUP(P28,KPI_Mapping!B:G,6,FALSE) -> AG0073
A29: =B29&C29 -> Hong KongAG0020_2 | B29: Hong Kong | C29: AG0020_2 | D29: Net Case Count - Agency in 2-3M | E29: =VLOOKUP(A29,G:K,5,FALSE) -> #N/A | G29: =H29&I29 -> IndonesiaAG0016 | H29: Indonesia | I29: AG0016 | J29: # of 1-Month Active Agents | K29: EDL
A30: =B30&C30 -> Hong KongAG0020_3 | B30: Hong Kong | C30: AG0020_3 | D30: Net Case Count - Agency in 4-12M | E30: =VLOOKUP(A30,G:K,5,FALSE) -> #N/A | G30: =H30&I30 -> IndonesiaAG0020 | H30: Indonesia | I30: AG0020 | J30: Net Case Count - Agency | K30: EDL
A31: =B31&C31 -> Hong KongAG0020_4 | B31: Hong Kong | C31: AG0020_4 | D31: Net Case Count - Agency 13+M | E31: =VLOOKUP(A31,G:K,5,FALSE) -> #N/A | G31: =H31&I31 -> IndonesiaAG0029 | H31: Indonesia | I31: AG0029 | J31: Total agent headcount (end of period) | K31: EDL
A32: =B32&C32 -> Hong KongAG0020_9 | B32: Hong Kong | C32: AG0020_9 | D32: Net Case Count - Agency in FA or equivalent | E32: =VLOOKUP(A32,G:K,5,FALSE) -> #N/A | G32: =H32&I32 -> IndonesiaAG0038 | H32: Indonesia | I32: AG0038 | J32: New recruits | K32: EDL
A33: =B33&C33 -> Hong KongAG0024 | B33: Hong Kong | C33: AG0024 | D33: No. of Sales Proposal Generated | E33: =VLOOKUP(A33,G:K,5,FALSE) -> #N/A | G33: =H33&I33 -> IndonesiaAG0041 | H33: Indonesia | I33: AG0041 | J33: # of 6-90 agents | K33: EDL
A34: =B34&C34 -> Hong KongAG0027 | B34: Hong Kong | C34: AG0027 | D34: $ APE from Agents in X tenure | E34: =VLOOKUP(A34,G:K,5,FALSE) -> #N/A | G34: =H34&I34 -> IndonesiaAG0043 | H34: Indonesia | I34: AG0043 | J34: New Recruits 3M Activation # | K34: EDL
A35: =B35&C35 -> Hong KongAG0027_1 | B35: Hong Kong | C35: AG0027_1 | D35: $ APE from Agents in X tenure in 0-1M | E35: =VLOOKUP(A35,G:K,5,FALSE) -> #N/A | G35: =H35&I35 -> IndonesiaAG0046 | H35: Indonesia | I35: AG0046 | J35: No of Terminations | K35: EDL
A36: =B36&C36 -> Hong KongAG0027_2 | B36: Hong Kong | C36: AG0027_2 | D36: $ APE from Agents in X tenure in 2-3M | E36: =VLOOKUP(A36,G:K,5,FALSE) -> #N/A | G36: =H36&I36 -> IndonesiaAG0051 | H36: Indonesia | I36: AG0051 | J36: Total # of Leaders (end of period) | K36: EDL
A37: =B37&C37 -> Hong KongAG0027_3 | B37: Hong Kong | C37: AG0027_3 | D37: $ APE from Agents in X tenure in 4-12M | E37: =VLOOKUP(A37,G:K,5,FALSE) -> #N/A | G37: =H37&I37 -> IndonesiaAG0051_1 | H37: Indonesia | I37: AG0051_1 | J37: Total # of Unit Managers | K37: EDL
A38: =B38&C38 -> Hong KongAG0027_4 | B38: Hong Kong | C38: AG0027_4 | D38: $ APE from Agents in X tenure 13+M | E38: =VLOOKUP(A38,G:K,5,FALSE) -> #N/A | G38: =H38&I38 -> IndonesiaAG0051_2 | H38: Indonesia | I38: AG0051_2 | J38: Total # of Leaders above Unit Manager level | K38: EDL
A39: =B39&C39 -> Hong KongAG0029 | B39: Hong Kong | C39: AG0029 | D39: Total agent headcount (end of period) | E39: =VLOOKUP(A39,G:K,5,FALSE) -> EDL | G39: =H39&I39 -> IndonesiaAG0054 | H39: Indonesia | I39: AG0054 | J39: Total # of Agents below Unit Manager level (end of period) | K39: Not Applicable
A40: =B40&C40 -> Hong KongAG0029_1 | B40: Hong Kong | C40: AG0029_1 | D40: Total agent headcount (end of period) in 0-1M | E40: =VLOOKUP(A40,G:K,5,FALSE) -> #N/A | G40: =H40&I40 -> IndonesiaAG0055 | H40: Indonesia | I40: AG0055 | J40: # of Active Recruiting Leaders | K40: EDL
... A43: =B43&C43 -> Hong KongAG0029_12 | B43: Hong Kong | C43: AG0029_12 | D43: Total agent headcount (end of period) in Top-tier Agents | E43: =VLOOKUP(A43,G:K,5,FALSE) -> #N/A | G43: =H43&I43 -> IndonesiaAG0060_1 | H43: Indonesia | I43: AG0060_1 | J43: # of Newly Promoted Leaders above UM | K43: EDL
A44: =B44&C44 -> Hong KongAG0029_12_1 | B44: Hong Kong | C44: AG0029_12_1 | D44: Total agent headcount (end of period) in pro-rated MDRT agents (>100% of pro-rated achievement) | E44: =VLOOKUP(A44,G:K,5,FALSE) -> #N/A | G44: =H44&I44 -> #N/A | H44: Indonesia | I44: #N/A | J44: # of Total Leader Promotions | K44: Anaplan Calculated
A45: =B45&C45 -> Hong KongAG0029_12_2 | B45: Hong Kong | C45: AG0029_12_2 | D45: Total agent headcount (end of period) in pro-rated MDRT agents (70-99% of pro-rated achievement) | E45: =VLOOKUP(A45,G:K,5,FALSE) -> #N/A | G45: =H45&I45 -> IndonesiaAG0072_1 | H45: Indonesia | I45: AG0072_1 | J45: # of Newly Demoted UM | K45: EDL
...

Sheet Sheet3
C18: PERIOD | D18: BU_CODE | E18: BU | F18: CHANNEL_CODE | G18: DISTRIBUTION_CHANNEL | H18: ACCOUNT | I18: ACCOUNT_ID | J18: MODE | K18: VALUE | N18: PERIOD | O18: BU_CODE | P18: BU | Q18: CHANNEL_CODE | R18: DISTRIBUTION_CHANNEL | S18: ACCOUNT | T18: ACCOUNT_ID | U18: MODE | V18: VALUE
C19: 46053 | D19: SG | E19: Singapore | F19: SG-MFA | G19: MFA | H19: # of Newly Promoted UM | I19: AG0060 | J19: M1 | K19: 7 | N19: 46053 | O19: SG | P19: Singapore | Q19: SG-MFA | R19: MFA | S19: # of Newly Promoted Leaders above UM | T19: AG0060_1 | U19: M1 | V19: 1
C20: 46053 | D20: SG | E20: Singapore | F20: SG-MAG | G20: MAG | H20: # of Newly Promoted UM | I20: AG0060 | J20: M1 | K20: 2 | N20: 46053 | O20: SG | P20: Singapore | Q20: SG-MAG | R20: MAG | S20: # of Newly Promoted Leaders above UM | T20: AG0060_1 | U20: M1 | V20: 1
C21: 46081 | D21: SG | E21: Singapore | F21: SG-MAG | G21: MAG | H21: # of Newly Promoted UM | I21: AG0060 | J21: M1 | K21: 1 | N21: 46081 | O21: SG | P21: Singapore | Q21: SG-MAG | R21: MAG | S21: # of Newly Promoted Leaders above UM | T21: AG0060_1 | U21: M1 | V21: 0
C22: 46081 | D22: SG | E22: Singapore | F22: SG-MFA | G22: MFA | H22: # of Newly Promoted UM | I22: AG0060 | J22: M1 | K22: 1 | N22: 46081 | O22: SG | P22: Singapore | Q22: SG-MFA | R22: MFA | S22: # of Newly Promoted Leaders above UM | T22: AG0060_1 | U22: M1 | V22: 0
C23: 46112 | D23: SG | E23: Singapore | F23: SG-MFA | G23: MFA | H23: # of Newly Promoted UM | I23: AG0060 | J23: M1 | K23: 0 | N23: 46112 | O23: SG | P23: Singapore | Q23: SG-MAG | R23: MAG | S23: # of Newly Promoted Leaders above UM | T23: AG0060_1 | U23: M1 | V23: 0
C24: 46112 | D24: SG | E24: Singapore | F24: SG-MAG | G24: MAG | H24: # of Newly Promoted UM | I24: AG0060 | J24: M1 | K24: 0 | N24: 46112 | O24: SG | P24: Singapore | Q24: SG-MFA | R24: MFA | S24: # of Newly Promoted Leaders above UM | T24: AG0060_1 | U24: M1 | V24: 0
C25: 46142 | D25: SG | E25: Singapore | F25: SG-MFA | G25: MFA | H25: # of Newly Promoted UM | I25: AG0060 | J25: M1 | K25: 0 | N25: 46142 | O25: SG | P25: Singapore | Q25: SG-MAG | R25: MAG | S25: # of Newly Promoted Leaders above UM | T25: AG0060_1 | U25: M1 | V25: 0
C26: 46142 | D26: SG | E26: Singapore | F26: SG-MAG | G26: MAG | H26: # of Newly Promoted UM | I26: AG0060 | J26: M1 | K26: 1 | N26: 46142 | O26: SG | P26: Singapore | Q26: SG-MFA | R26: MFA | S26: # of Newly Promoted Leaders above UM | T26: AG0060_1 | U26: M1 | V26: 0
C27: 46173 | D27: SG | E27: Singapore | F27: SG-MAG | G27: MAG | H27: # of Newly Promoted UM | I27: AG0060 | J27: M1 | K27: 0 | N27: 46173 | O27: SG | P27: Singapore | Q27: SG-MAG | R27: MAG | S27: # of Newly Promoted Leaders above UM | T27: AG0060_1 | U27: M1 | V27: 0
C28: 46173 | D28: SG | E28: Singapore | F28: SG-MFA | G28: MFA | H28: # of Newly Promoted UM | I28: AG0060 | J28: M1 | K28: 2 | N28: 46173 | O28: SG | P28: Singapore | Q28: SG-MFA | R28: MFA | S28: # of Newly Promoted Leaders above UM | T28: AG0060_1 | U28: M1 | V28: 0
C29: 46203 | D29: SG | E29: Singapore | F29: SG-MAG | G29: MAG | H29: # of Newly Promoted UM | I29: AG0060 | J29: M1 | K29: 2 | N29: 46203 | O29: SG | P29: Singapore | Q29: SG-MFA | R29: MFA | S29: # of Newly Promoted Leaders above UM | T29: AG0060_1 | U29: M1 | V29: 1
C30: 46203 | D30: SG | E30: Singapore | F30: SG-MFA | G30: MFA | H30: # of Newly Promoted UM | I30: AG0060 | J30: M1 | K30: 1 | N30: 46203 | O30: SG | P30: Singapore | Q30: SG-MAG | R30: MAG | S30: # of Newly Promoted Leaders above UM | T30: AG0060_1 | U30: M1 | V30: 0
... C32: 46234 | D32: SG | E32: Singapore | F32: SG-MFA | G32: MFA | H32: # of Newly Promoted UM | I32: AG0060 | J32: M1 | K32: 3 | N32: 46234 | O32: SG | P32: Singapore | Q32: SG-MAG | R32: MAG | S32: # of Newly Promoted Leaders above UM | T32: AG0060_1 | U32: M1 | V32: 0
J39: =148/212 -> 0.69811321
F43: =160/2088 -> 0.076628352

Sheet KPI_Mapping
B1: anaplan_metric | D1: edl_metric | F1: pbi_metric | G1: Account_id
B2: Submitted APE | D2: Submitted APE | F2: Submitted APE | G2: AG0002
B3: # of 1-Month Active Agents | D3: # of 1-Month Active Agents | F3: # of 1-Month Active Agents | G3: AG0016
B4: # of 1-Month Active Agents in 0-1M | D4: # of 1-Month Active Agents in 0-1M | F4: # of 1-Month Active Agents in 0-1M | G4: AG0016_1
B5: # of 1-Month Active Agents in 2-3M | D5: # of 1-Month Active Agents in 2-3M | F5: # of 1-Month Active Agents in 2-3M | G5: AG0016_2
B6: # of 1-Month Active Agents in 4-12M | D6: # of 1-Month Active Agents in 4-12M | F6: # of 1-Month Active Agents in 4-12M | G6: AG0016_3
B7: # of 1-Month Active Agents 13+M | D7: # of 1-Month Active Agents 13+M | F7: # of 1-Month Active Agents 13+M | G7: AG0016_4
B8: # of 1-Month Active Agents in FA or equivalent | D8: # of 1-Month Active Agents in FA or equivalent | F8: # of 1-Month Active Agents in FA or equivalent | G8: AG0016_9
B9: # of 1-Month Active Agents in UM | D9: # of 1-Month Active Agents in UM | F9: # of 1-Month Active Agents in UM | G9: AG0016_10
B10: # of 1-Month Active Agents in Leaders above UM | D10: # of 1-Month Active Agents in Leaders above UM | F10: # of 1-Month Active Agents in Leaders above UM | G10: AG0016_11
B11: # of 1-Month Active Top-tier Agents | D11: # of 1-Month Active Top-tier Agents | F11: # of 1-Month Active Top-tier Agents | G11: AG0016_12
B12: # of 1-Month Active Agents in pro-rated MDRT agents (>100%) | D12: # of 1-Month Active Agents in pro-rated MDRT agents (>100% of pro-rated achievement) | F12: # of 1-Month Active Agents in pro-rated MDRT agents (>100%) | G12: AG0016_12_1
... B110: $ APE from Manulife Pro - Total | D110: $ APE from Manulife Pro - Total | F110: $ APE from Manulife Pro - Total | G110: AG0077
